<mujoco model="empty_floor">
  <compiler angle="radian" />

  <option timestep="0.001" gravity="0 0 -9.81" integrator="implicitfast" impratio="10">
      <flag contact="enable" energy="enable" gravity="enable" />
  </option>

  <visual>
    <rgba haze="0.15 0.25 0.35 1" />
    <global azimuth="120" elevation="-20" />
  </visual>

  <asset>
    <mesh name="table" file="D:\WorkFiles\robopal\robopal\assets\scenes\../objects/table/table.STL" scale="1.0 1.0 0.66" />

    <texture type="skybox" builtin="gradient" rgb1="0.68 0.68 0.68" rgb2="0.3 0.3 0.3" width="512" height="3072" />
    <texture name="groundplane" type="2d" builtin="checker" mark="edge" rgb1="0.68 0.68 0.68" rgb2="0.8 0.8 0.8" markrgb="0.68 0.68 0.68" width="300" height="300" />
    <material name="groundplane" reflectance="0.2" shininess="0.0" specular="0.0" texrepeat="5 5" texture="groundplane" texuniform="true" />

    <texture name="wood" type="2d" file="D:\WorkFiles\robopal\robopal\commons/../assets/textures\wood.png" />
    <material name="wood" texture="wood" texrepeat="1 1" texuniform="true" rgba="0.68 0.68 0.68 1" />
  <texture file="D:\WorkFiles\robopal\robopal\commons/../assets/textures\white-marble.png" type="2d" name="aluminum" />
        <material name="cylinder" reflectance="0.5" texrepeat="5 5" texture="aluminum" texuniform="true" />
    <texture file="D:\WorkFiles\robopal\robopal\commons/../assets/textures\white-marble.png" type="2d" name="aluminum2" />
        <material name="cylinder2" reflectance="0.5" texrepeat="5 5" texture="aluminum" texuniform="true" />
    <mesh name="0_base_link" file="D:\WorkFiles\robopal\robopal\assets\models\manipulators\DianaMed\meshes/base_link.STL" />
        <mesh name="0_link1" file="D:\WorkFiles\robopal\robopal\assets\models\manipulators\DianaMed\meshes/link1.STL" />
        <mesh name="0_link2" file="D:\WorkFiles\robopal\robopal\assets\models\manipulators\DianaMed\meshes/link2.STL" />
        <mesh name="0_link3" file="D:\WorkFiles\robopal\robopal\assets\models\manipulators\DianaMed\meshes/link3.STL" />
        <mesh name="0_link4" file="D:\WorkFiles\robopal\robopal\assets\models\manipulators\DianaMed\meshes/link4.STL" />
        <mesh name="0_link5" file="D:\WorkFiles\robopal\robopal\assets\models\manipulators\DianaMed\meshes/link5.STL" />
        <mesh name="0_link6" file="D:\WorkFiles\robopal\robopal\assets\models\manipulators\DianaMed\meshes/link6.STL" />
        <mesh name="0_link7" file="D:\WorkFiles\robopal\robopal\assets\models\manipulators\DianaMed\meshes/link7.STL" />
    <mesh name="1_base_link" file="D:\WorkFiles\robopal\robopal\assets\models\manipulators\DianaMed\meshes/base_link.STL" />
        <mesh name="1_link1" file="D:\WorkFiles\robopal\robopal\assets\models\manipulators\DianaMed\meshes/link1.STL" />
        <mesh name="1_link2" file="D:\WorkFiles\robopal\robopal\assets\models\manipulators\DianaMed\meshes/link2.STL" />
        <mesh name="1_link3" file="D:\WorkFiles\robopal\robopal\assets\models\manipulators\DianaMed\meshes/link3.STL" />
        <mesh name="1_link4" file="D:\WorkFiles\robopal\robopal\assets\models\manipulators\DianaMed\meshes/link4.STL" />
        <mesh name="1_link5" file="D:\WorkFiles\robopal\robopal\assets\models\manipulators\DianaMed\meshes/link5.STL" />
        <mesh name="1_link6" file="D:\WorkFiles\robopal\robopal\assets\models\manipulators\DianaMed\meshes/link6.STL" />
        <mesh name="1_link7" file="D:\WorkFiles\robopal\robopal\assets\models\manipulators\DianaMed\meshes/link7.STL" />
    <mesh name="0_electric_gripper_base" file="D:\WorkFiles\robopal\robopal\assets\models\grippers\rethink_gripper\meshes/electric_gripper_base.stl" />
        <mesh name="0_standard_narrow" file="D:\WorkFiles\robopal\robopal\assets\models\grippers\rethink_gripper\meshes/standard_narrow.stl" />
        <mesh name="0_half_round_tip" file="D:\WorkFiles\robopal\robopal\assets\models\grippers\rethink_gripper\meshes/half_round_tip.stl" />
        <mesh name="0_connector_plate" file="D:\WorkFiles\robopal\robopal\assets\models\grippers\rethink_gripper\meshes/connector_plate.stl" />
    <mesh name="1_electric_gripper_base" file="D:\WorkFiles\robopal\robopal\assets\models\grippers\rethink_gripper\meshes/electric_gripper_base.stl" />
        <mesh name="1_standard_narrow" file="D:\WorkFiles\robopal\robopal\assets\models\grippers\rethink_gripper\meshes/standard_narrow.stl" />
        <mesh name="1_half_round_tip" file="D:\WorkFiles\robopal\robopal\assets\models\grippers\rethink_gripper\meshes/half_round_tip.stl" />
        <mesh name="1_connector_plate" file="D:\WorkFiles\robopal\robopal\assets\models\grippers\rethink_gripper\meshes/connector_plate.stl" />
    </asset>

  <worldbody>
    
    <geom condim="3" material="groundplane" name="floor" pos="0 0 0" size="3 3 .125" type="plane" />
    <light diffuse=".8 .8 .8" dir="0 -.15 -1" directional="false" pos="1 1 8.0" specular="0.3 0.3 0.3" castshadow="false" />
    <light diffuse=".8 .8 .8" dir="0 -.15 -1" directional="false" pos="-3. -3. 8.0" specular="0.3 0.3 0.3" castshadow="false" />
    
    <camera mode="fixed" name="frontview" pos="1.3 0 0.9" quat="0.56 0.43 0.43 0.56" />
    
    <camera mode="fixed" name="birdview" pos="-0.2 0 3.0" quat="0.7071 0 0 0.7071" />
    
    <camera mode="fixed" name="agentview" pos="0.5 0 1.35" quat="0.653 0.271 0.271 0.653" />
    
    <camera mode="fixed" name="sideview" pos="-0.05651774593317116 1.2761224129427358 1.4879572214102434" quat="0.009905065491771751 0.006877963156909582 0.5912228352893879 0.806418094001364" />

    <body name="table" pos="1.0 0.3 0.0" euler="0 0 0">
        <include file="objects/table/table.xml" />
    </body>

  <body name="0_mount_base_link" pos="1.2 0.0 0.3" quat="0 0 0 1">
      		<geom pos="0 0 -0.14" size="0.07 0.14" type="cylinder" friction="1 0.005 0.0001" />
      		<geom pos="0 0 -0.14" material="cylinder" size="0.072 0.16" type="cylinder" conaffinity="0" contype="0" />
        <body name="0_base_link">
            <geom type="mesh" contype="0" conaffinity="0" group="1" pos="0 0 0" rgba="1 1 1 1" mesh="0_base_link" />
            <body name="0_link1" pos="8.7058e-05 -0.00063474 0.2985" quat="-3.67321e-06 1 0 0">
                <inertial pos="4.57641e-06 -0.0439746 0.0236145" quat="0.685631 -0.172505 0.172644 0.685818" mass="2.72698" diaginertia="0.0122186 0.0113371 0.00692616" />
                <joint name="0_j1" pos="0 0 0" axis="0 0 1" limited="true" range="-2.56 2.56" damping="0.05" />
                <geom type="mesh" contype="0" conaffinity="0" group="1" rgba="1 1 1 1" mesh="0_link1" />

                <body name="0_link2" pos="0 0 -0.00092116" quat="0.707105 0.707108 0 0">
                    <inertial pos="8.26088e-06 -0.040728 -0.0363117" quat="0.596612 0.379593 -0.379572 0.596564" mass="3.18168" diaginertia="0.0189254 0.0180721 0.00757505" />
                    <joint name="0_j2" pos="0 0 0" axis="0 0 -1" limited="true" range="-1.57 1.57" damping="0.1" />
                    <geom type="mesh" contype="0" conaffinity="0" group="1" rgba="1 1 1 1" mesh="0_link2" />

                    <body name="0_link3" pos="0 -0.45818 0.0005" quat="0.707105 -0.707108 0 0">
                        <inertial pos="0.0148079 -0.0159925 0.127198" quat="0.874546 -0.136758 -0.0611978 0.461217" mass="3.93616" diaginertia="0.0569273 0.0547312 0.00935482" />
                        <joint name="0_j3" pos="0 0 0" axis="0 0 -1" limited="true" range="-2.56 2.56" damping="0.05" />
                        <geom type="mesh" contype="0" conaffinity="0" group="1" rgba="1 1 1 1" mesh="0_link3" />

                        <body name="0_link4" pos="0.064454 0.0005 -0.00070508" quat="0.707105 0.707108 0 0">
                            <inertial pos="-0.0145884 -0.0117113 -0.0406158" quat="0.00473736 0.651043 0.564294 0.507635" mass="1.58469" diaginertia="0.00499445 0.00482606 0.00267104" />
                            <joint name="0_j4" pos="0 0 0" axis="0 0 1" limited="true" range="0.0 3.05" damping="0.05" />
                            <geom type="mesh" contype="0" conaffinity="0" group="1" rgba="1 1 1 1" mesh="0_link4" />

                            <body name="0_link5" pos="-0.052254 -0.45668 0.0005" quat="0.707105 -0.707108 0 0">
                                <inertial pos="-0.00209922 0.0288297 0.222845" quat="0.985159 0.138333 -0.00891494 0.101222" mass="1.92688" diaginertia="0.0293358 0.0290794 0.00210656" />
                                <joint name="0_j5" pos="0 0 0" axis="0 0 -1" limited="true" range="-3.05 3.05" damping="0.05" />
                                <geom type="mesh" contype="0" conaffinity="0" group="1" rgba="1 1 1 1" mesh="0_link5" />
                                
                                <body name="0_link6" pos="0 -0.005 -1.1713e-05" quat="-2.59734e-06 -2.59735e-06 -0.707108 -0.707105">
                                    <inertial pos="0.038358 -0.00071885 -0.0021112" quat="0.0131349 0.678937 -0.0198942 0.733809" mass="1.7304" diaginertia="0.005268 0.00492614 0.00345065" />
                                    <joint name="0_j6" pos="0 0 0" axis="0 0 1" limited="true" range="-3.14 3.14" damping="0.05" />
                                    <geom type="mesh" contype="0" conaffinity="0" group="1" rgba="1 1 1 1" mesh="0_link6" />
                                    
                                    <body name="0_link7" pos="0.076728 -0.1059 0" quat="0.707105 -0.707108 0 0">
                                        <joint name="0_j7" pos="0 0 0" axis="0 0 -1" limited="true" range="-3.14 3.14" damping="0.001" />
                                        <inertial pos="0.00068467 1.5999e-05 0.020834" quat="0.000547318 0.708756 -0.000448023 0.705453" mass="0.16696" diaginertia="0.000143911 8.8902e-05 8.75358e-05" />
                                        <geom type="mesh" contype="0" conaffinity="0" group="1" rgba="1 1 1 1" mesh="0_link7" />
                                        <geom name="0_link7_collision" type="mesh" rgba="1 1 1 1" mesh="0_link7" />
                                        <body name="0_attachment" pos="0 0 0" quat="0 1 0 0">
                                            <site name="0_attachment_site" />
                                        <body name="0_gripper_base">
            <site name="0_ft_frame" pos="0 0 0" size="0.01 0.01 0.01" rgba="1 0 0 1" type="sphere" group="1" />
            <inertial pos="0 0 0" quat="-0.5 0.5 0.5 0.5" mass="0.0001" diaginertia="3e-08 2e-08 2e-08" />
            <geom type="mesh" contype="0" conaffinity="0" group="1" mesh="0_connector_plate" name="0_connector_plate" pos="0 0 0.0018" rgba="0.499 0.499 0.499 1" />
            <geom type="mesh" contype="0" conaffinity="0" group="1" mesh="0_electric_gripper_base" name="0_electric_gripper_base" pos="0 0 0.0194" rgba="0.499 0.499 0.499 1" />
            <geom size="0.029 0.05" quat="0 0 0.707107 0.707107" type="cylinder" group="0" name="0_gripper_base_col" pos="0.004 0.0 0.04" />
            
            <body name="0_eef" pos="0 0 0.109" quat="0 1 0 0">
                <site name="0_grip_site" pos="0 0 0" size="0.005" rgba="1 0 0 0.1" type="sphere" group="1" />
                <site name="0_ee_x" pos="0.2 0 0" size="0.005 .2" quat="0.707105  0 0.707108 0 " rgba="1 0 0 0.1" type="cylinder" group="1" />
                <site name="0_ee_y" pos="0 0.2 0" size="0.005 .2" quat="0.707105 0.707108 0 0" rgba="0 1 0 0.1" type="cylinder" group="1" />
                <site name="0_ee_z" pos="0 0 0.2" size="0.005 .2" quat="1 0 0 0" rgba="0 0 1 0.5" type="cylinder" group="1" />
                <site name="0_ee_x_ne" pos="-0.2 0 0" size="0.005 .2" quat="0.707105  0 0.707108 0 " rgba="1 1 1 0.1" type="cylinder" group="1" />
                <site name="0_ee_y_ne" pos="0 -0.2 0" size="0.005 .2" quat="0.707105 0.707108 0 0" rgba="1 1 1 0.1" type="cylinder" group="1" />
                <site name="0_ee_z_ne" pos="0 0 -0.2" size="0.005 .2" quat="1 0 0 0" rgba="1 1 1 0.1" type="cylinder" group="1" />
            </body>
            <body name="0_l_finger" pos="0 0.01 0.0444">
                <inertial pos="0 0 0" quat="0 0 0 -1" mass="0.0001" diaginertia="0.001 0.001 0.001" />
                <joint name="0_l_finger_joint" pos="0 0 0" axis="0 1 0" type="slide" limited="true" range="-0.0115 0.020833" damping="100" armature="1.0" frictionloss="1.0" />
                <geom name="0_0_l_finger" quat="0 0 0 -1" type="mesh" contype="0" conaffinity="0" group="1" mesh="0_standard_narrow" rgba="0.499 0.499 0.499 1" />
                <geom size="0.005 0.00675 0.0375" pos="0 0.01725 0.04" quat="0 0 0 -1" type="box" group="0" conaffinity="1" contype="0" name="0_l_finger_g0" friction="0 0 0" />
                <geom size="0.005 0.025 0.0085" pos="-0.005 -0.003 0.0083" quat="0 0 0 -1" type="box" group="0" conaffinity="1" contype="0" name="0_l_finger_g1" friction="0 0 0" />
                <body name="0_l_finger_tip" pos="0 0.01725 0.075">
                    <inertial pos="0 0 0" quat="0 0 0 1" mass="0.0001" diaginertia="0.001 0.001 0.001" />
                    <geom name="0_l_fingertip_g0_vis" quat="0 0 0 1" type="mesh" contype="0" conaffinity="0" group="1" mesh="0_half_round_tip" rgba="0.499 0.499 0.499 1" />
                    <geom size="0.004 0.004 0.0185" pos="0 -0.0045 -0.015" quat="0 0 0 -1" type="box" group="0" conaffinity="1" contype="0" condim="4" name="0_l_fingertip_g0" friction="1 0.05 0.01" />
                    <geom size="0.0035 0.004 0.0165" pos="0 -0.0047 -0.017" type="box" conaffinity="1" contype="0" name="0_l_fingerpad_g0" condim="4" friction="1 0.05 0.01" />
                </body>
            </body>
            <body name="0_r_finger" pos="0 -0.01 0.0444">
                <inertial pos="0 0 0" mass="0.0001" diaginertia="0.001 0.001 0.001" />
                <joint name="0_r_finger_joint" pos="0 0 0" axis="0 -1 0" type="slide" limited="true" range="-0.020833 0.0115" damping="100" armature="1.0" frictionloss="1.0" />
                <geom name="0_0_r_finger" type="mesh" contype="0" conaffinity="0" group="1" mesh="0_standard_narrow" rgba="0.499 0.499 0.499 1" />
                <geom size="0.005 0.00675 0.0375" pos="0 -0.01725 0.04" type="box" group="0" conaffinity="1" contype="0" name="0_r_finger_g0" friction="0 0 0" />
                <geom size="0.005 0.025 0.0085" pos="0.005 0.003 0.0083" type="box" group="0" conaffinity="1" contype="0" name="0_r_finger_g1" friction="0 0 0" />
                <body name="0_r_finger_tip" pos="0 -0.01725 0.075">
                    <inertial pos="0 0 0" mass="0.0001" diaginertia="0.001 0.001 0.001" />
                    <geom name="0_r_fingertip_g0_vis" type="mesh" contype="0" conaffinity="0" group="1" mesh="0_half_round_tip" rgba="0.499 0.499 0.499 1" />
                    <geom size="0.004 0.004 0.0185" pos="0 0.0045 -0.015" type="box" group="0" conaffinity="1" contype="0" condim="4" name="0_r_fingertip_g0" friction="1 0.05 0.01" />
                    <geom size="0.0035 0.004 0.0165" pos="0 0.0047 -0.017" type="box" conaffinity="1" contype="0" condim="4" name="0_r_fingerpad_g0" friction="1 0.05 0.01" />
                </body>
            </body>
        </body>
    </body>
                                    </body>
                                </body>
                            </body>
                        </body>
                    </body>
                </body>
            </body>
        </body>
    </body>
    <body name="1_mount_base_link" pos="-0.4 0.0 0.3" quat="1 0 0 0">
      		<geom pos="0 0 -0.14" size="0.07 0.14" type="cylinder" friction="1 0.005 0.0001" />
      		<geom pos="0 0 -0.14" material="cylinder" size="0.072 0.16" type="cylinder" conaffinity="0" contype="0" />
        <body name="1_base_link">
            <geom type="mesh" contype="0" conaffinity="0" group="1" pos="0 0 0" rgba="1 1 1 1" mesh="1_base_link" />
            <body name="1_link1" pos="8.7058e-05 -0.00063474 0.2985" quat="-3.67321e-06 1 0 0">
                <inertial pos="4.57641e-06 -0.0439746 0.0236145" quat="0.685631 -0.172505 0.172644 0.685818" mass="2.72698" diaginertia="0.0122186 0.0113371 0.00692616" />
                <joint name="1_j1" pos="0 0 0" axis="0 0 1" limited="true" range="-2.56 2.56" damping="0.05" />
                <geom type="mesh" contype="0" conaffinity="0" group="1" rgba="1 1 1 1" mesh="1_link1" />

                <body name="1_link2" pos="0 0 -0.00092116" quat="0.707105 0.707108 0 0">
                    <inertial pos="8.26088e-06 -0.040728 -0.0363117" quat="0.596612 0.379593 -0.379572 0.596564" mass="3.18168" diaginertia="0.0189254 0.0180721 0.00757505" />
                    <joint name="1_j2" pos="0 0 0" axis="0 0 -1" limited="true" range="-1.57 1.57" damping="0.1" />
                    <geom type="mesh" contype="0" conaffinity="0" group="1" rgba="1 1 1 1" mesh="1_link2" />

                    <body name="1_link3" pos="0 -0.45818 0.0005" quat="0.707105 -0.707108 0 0">
                        <inertial pos="0.0148079 -0.0159925 0.127198" quat="0.874546 -0.136758 -0.0611978 0.461217" mass="3.93616" diaginertia="0.0569273 0.0547312 0.00935482" />
                        <joint name="1_j3" pos="0 0 0" axis="0 0 -1" limited="true" range="-2.56 2.56" damping="0.05" />
                        <geom type="mesh" contype="0" conaffinity="0" group="1" rgba="1 1 1 1" mesh="1_link3" />

                        <body name="1_link4" pos="0.064454 0.0005 -0.00070508" quat="0.707105 0.707108 0 0">
                            <inertial pos="-0.0145884 -0.0117113 -0.0406158" quat="0.00473736 0.651043 0.564294 0.507635" mass="1.58469" diaginertia="0.00499445 0.00482606 0.00267104" />
                            <joint name="1_j4" pos="0 0 0" axis="0 0 1" limited="true" range="0.0 3.05" damping="0.05" />
                            <geom type="mesh" contype="0" conaffinity="0" group="1" rgba="1 1 1 1" mesh="1_link4" />

                            <body name="1_link5" pos="-0.052254 -0.45668 0.0005" quat="0.707105 -0.707108 0 0">
                                <inertial pos="-0.00209922 0.0288297 0.222845" quat="0.985159 0.138333 -0.00891494 0.101222" mass="1.92688" diaginertia="0.0293358 0.0290794 0.00210656" />
                                <joint name="1_j5" pos="0 0 0" axis="0 0 -1" limited="true" range="-3.05 3.05" damping="0.05" />
                                <geom type="mesh" contype="0" conaffinity="0" group="1" rgba="1 1 1 1" mesh="1_link5" />
                                
                                <body name="1_link6" pos="0 -0.005 -1.1713e-05" quat="-2.59734e-06 -2.59735e-06 -0.707108 -0.707105">
                                    <inertial pos="0.038358 -0.00071885 -0.0021112" quat="0.0131349 0.678937 -0.0198942 0.733809" mass="1.7304" diaginertia="0.005268 0.00492614 0.00345065" />
                                    <joint name="1_j6" pos="0 0 0" axis="0 0 1" limited="true" range="-3.14 3.14" damping="0.05" />
                                    <geom type="mesh" contype="0" conaffinity="0" group="1" rgba="1 1 1 1" mesh="1_link6" />
                                    
                                    <body name="1_link7" pos="0.076728 -0.1059 0" quat="0.707105 -0.707108 0 0">
                                        <joint name="1_j7" pos="0 0 0" axis="0 0 -1" limited="true" range="-3.14 3.14" damping="0.001" />
                                        <inertial pos="0.00068467 1.5999e-05 0.020834" quat="0.000547318 0.708756 -0.000448023 0.705453" mass="0.16696" diaginertia="0.000143911 8.8902e-05 8.75358e-05" />
                                        <geom type="mesh" contype="0" conaffinity="0" group="1" rgba="1 1 1 1" mesh="1_link7" />
                                        <geom name="1_link7_collision" type="mesh" rgba="1 1 1 1" mesh="1_link7" />
                                        <body name="1_attachment" pos="0 0 0" quat="0 1 0 0">
                                            <site name="1_attachment_site" />
                                        <body name="1_gripper_base">
            <site name="1_ft_frame" pos="0 0 0" size="0.01 0.01 0.01" rgba="1 0 0 1" type="sphere" group="1" />
            <inertial pos="0 0 0" quat="-0.5 0.5 0.5 0.5" mass="0.0001" diaginertia="3e-08 2e-08 2e-08" />
            <geom type="mesh" contype="0" conaffinity="0" group="1" mesh="1_connector_plate" name="1_connector_plate" pos="0 0 0.0018" rgba="0.499 0.499 0.499 1" />
            <geom type="mesh" contype="0" conaffinity="0" group="1" mesh="1_electric_gripper_base" name="1_electric_gripper_base" pos="0 0 0.0194" rgba="0.499 0.499 0.499 1" />
            <geom size="0.029 0.05" quat="0 0 0.707107 0.707107" type="cylinder" group="0" name="1_gripper_base_col" pos="0.004 0.0 0.04" />
            
            <body name="1_eef" pos="0 0 0.109" quat="0 1 0 0">
                <site name="1_grip_site" pos="0 0 0" size="0.005" rgba="1 0 0 0.1" type="sphere" group="1" />
                <site name="1_ee_x" pos="0.2 0 0" size="0.005 .2" quat="0.707105  0 0.707108 0 " rgba="1 0 0 0.1" type="cylinder" group="1" />
                <site name="1_ee_y" pos="0 0.2 0" size="0.005 .2" quat="0.707105 0.707108 0 0" rgba="0 1 0 0.1" type="cylinder" group="1" />
                <site name="1_ee_z" pos="0 0 0.2" size="0.005 .2" quat="1 0 0 0" rgba="0 0 1 0.5" type="cylinder" group="1" />
                <site name="1_ee_x_ne" pos="-0.2 0 0" size="0.005 .2" quat="0.707105  0 0.707108 0 " rgba="1 1 1 0.1" type="cylinder" group="1" />
                <site name="1_ee_y_ne" pos="0 -0.2 0" size="0.005 .2" quat="0.707105 0.707108 0 0" rgba="1 1 1 0.1" type="cylinder" group="1" />
                <site name="1_ee_z_ne" pos="0 0 -0.2" size="0.005 .2" quat="1 0 0 0" rgba="1 1 1 0.1" type="cylinder" group="1" />
            </body>
            <body name="1_l_finger" pos="0 0.01 0.0444">
                <inertial pos="0 0 0" quat="0 0 0 -1" mass="0.0001" diaginertia="0.001 0.001 0.001" />
                <joint name="1_l_finger_joint" pos="0 0 0" axis="0 1 0" type="slide" limited="true" range="-0.0115 0.020833" damping="100" armature="1.0" frictionloss="1.0" />
                <geom name="1_1_l_finger" quat="0 0 0 -1" type="mesh" contype="0" conaffinity="0" group="1" mesh="1_standard_narrow" rgba="0.499 0.499 0.499 1" />
                <geom size="0.005 0.00675 0.0375" pos="0 0.01725 0.04" quat="0 0 0 -1" type="box" group="0" conaffinity="1" contype="0" name="1_l_finger_g0" friction="0 0 0" />
                <geom size="0.005 0.025 0.0085" pos="-0.005 -0.003 0.0083" quat="0 0 0 -1" type="box" group="0" conaffinity="1" contype="0" name="1_l_finger_g1" friction="0 0 0" />
                <body name="1_l_finger_tip" pos="0 0.01725 0.075">
                    <inertial pos="0 0 0" quat="0 0 0 1" mass="0.0001" diaginertia="0.001 0.001 0.001" />
                    <geom name="1_l_fingertip_g0_vis" quat="0 0 0 1" type="mesh" contype="0" conaffinity="0" group="1" mesh="1_half_round_tip" rgba="0.499 0.499 0.499 1" />
                    <geom size="0.004 0.004 0.0185" pos="0 -0.0045 -0.015" quat="0 0 0 -1" type="box" group="0" conaffinity="1" contype="0" condim="4" name="1_l_fingertip_g0" friction="1 0.05 0.01" />
                    <geom size="0.0035 0.004 0.0165" pos="0 -0.0047 -0.017" type="box" conaffinity="1" contype="0" name="1_l_fingerpad_g0" condim="4" friction="1 0.05 0.01" />
                </body>
            </body>
            <body name="1_r_finger" pos="0 -0.01 0.0444">
                <inertial pos="0 0 0" mass="0.0001" diaginertia="0.001 0.001 0.001" />
                <joint name="1_r_finger_joint" pos="0 0 0" axis="0 -1 0" type="slide" limited="true" range="-0.020833 0.0115" damping="100" armature="1.0" frictionloss="1.0" />
                <geom name="1_1_r_finger" type="mesh" contype="0" conaffinity="0" group="1" mesh="1_standard_narrow" rgba="0.499 0.499 0.499 1" />
                <geom size="0.005 0.00675 0.0375" pos="0 -0.01725 0.04" type="box" group="0" conaffinity="1" contype="0" name="1_r_finger_g0" friction="0 0 0" />
                <geom size="0.005 0.025 0.0085" pos="0.005 0.003 0.0083" type="box" group="0" conaffinity="1" contype="0" name="1_r_finger_g1" friction="0 0 0" />
                <body name="1_r_finger_tip" pos="0 -0.01725 0.075">
                    <inertial pos="0 0 0" mass="0.0001" diaginertia="0.001 0.001 0.001" />
                    <geom name="1_r_fingertip_g0_vis" type="mesh" contype="0" conaffinity="0" group="1" mesh="1_half_round_tip" rgba="0.499 0.499 0.499 1" />
                    <geom size="0.004 0.004 0.0185" pos="0 0.0045 -0.015" type="box" group="0" conaffinity="1" contype="0" condim="4" name="1_r_fingertip_g0" friction="1 0.05 0.01" />
                    <geom size="0.0035 0.004 0.0165" pos="0 0.0047 -0.017" type="box" conaffinity="1" contype="0" condim="4" name="1_r_fingerpad_g0" friction="1 0.05 0.01" />
                </body>
            </body>
        </body>
    </body>
                                    </body>
                                </body>
                            </body>
                        </body>
                    </body>
                </body>
            </body>
        </body>
    </body>
    <site name="goal_site0" pos="0.4 0.0 0.5" size="0.02 0.02 0.02" rgba="1 0 0 1" type="sphere" /><site name="goal_site1" pos="0.4 0.0 0.5" size="0.02 0.02 0.02" rgba="0 1 0 1" type="sphere" /></worldbody>
<actuator><motor name="0_a1" ctrllimited="true" ctrlrange="-80.0 80.0" joint="0_j1" />
        <motor name="0_a2" ctrllimited="true" ctrlrange="-80.0 80.0" joint="0_j2" />
        <motor name="0_a3" ctrllimited="true" ctrlrange="-80.0 80.0" joint="0_j3" />
        <motor name="0_a4" ctrllimited="true" ctrlrange="-80.0 80.0" joint="0_j4" />
        <motor name="0_a5" ctrllimited="true" ctrlrange="-80.0 80.0" joint="0_j5" />
        <motor name="0_a6" ctrllimited="true" ctrlrange="-80.0 80.0" joint="0_j6" />
        <motor name="0_a7" ctrllimited="true" ctrlrange="-80.0 80.0" joint="0_j7" />
    <motor name="1_a1" ctrllimited="true" ctrlrange="-80.0 80.0" joint="1_j1" />
        <motor name="1_a2" ctrllimited="true" ctrlrange="-80.0 80.0" joint="1_j2" />
        <motor name="1_a3" ctrllimited="true" ctrlrange="-80.0 80.0" joint="1_j3" />
        <motor name="1_a4" ctrllimited="true" ctrlrange="-80.0 80.0" joint="1_j4" />
        <motor name="1_a5" ctrllimited="true" ctrlrange="-80.0 80.0" joint="1_j5" />
        <motor name="1_a6" ctrllimited="true" ctrlrange="-80.0 80.0" joint="1_j6" />
        <motor name="1_a7" ctrllimited="true" ctrlrange="-80.0 80.0" joint="1_j7" />
    <position ctrllimited="true" ctrlrange="-0.020833 0.0115" joint="0_r_finger_joint" kp="1000" name="0_gripper_r_finger_joint" forcelimited="true" forcerange="-20 20" />
        <position ctrllimited="true" ctrlrange="-0.020833 0.0115" joint="0_l_finger_joint" kp="1000" name="0_gripper_l_finger_joint" forcelimited="true" forcerange="-20 20" />
    <position ctrllimited="true" ctrlrange="-0.020833 0.0115" joint="1_r_finger_joint" kp="1000" name="1_gripper_r_finger_joint" forcelimited="true" forcerange="-20 20" />
        <position ctrllimited="true" ctrlrange="-0.020833 0.0115" joint="1_l_finger_joint" kp="1000" name="1_gripper_l_finger_joint" forcelimited="true" forcerange="-20 20" />
    </actuator><default /><contact /><sensor><force name="0_force_ee" site="0_ft_frame" />
        <torque name="0_torque_ee" site="0_ft_frame" />
    <force name="1_force_ee" site="1_ft_frame" />
        <torque name="1_torque_ee" site="1_ft_frame" />
    </sensor><equality><joint joint1="0_r_finger_joint" joint2="0_l_finger_joint" />
    <joint joint1="1_r_finger_joint" joint2="1_l_finger_joint" />
    </equality><tendon /></mujoco>